<?xml version="1.0" encoding="utf-8"?>
<!-- This URDF was automatically created by SolidWorks to URDF Exporter! Originally created by Stephen Brawner (brawner@gmail.com) 
     Commit Version: 1.6.0-4-g7f85cfe  Build Version: 1.6.7995.38578
     For more information, please see http://wiki.ros.org/sw_urdf_exporter -->
<robot
  name="ros2Model">
  <link
    name="world" />
  <link
    name="base_link">
    <inertial>
      <origin
        xyz="0 0 0"
        rpy="0 0 0" />
      <mass
        value="0.001" />
      <inertia
        ixx="0.0001"
        ixy="0"
        ixz="0"
        iyy="0.0001"
        iyz="0"
        izz="0.0001" />
    </inertial>
    <visual>
      <origin
        xyz="0 0 0"
        rpy="0 0 0" />
      <geometry>
        <box
          size="0.1 0.1 0.1" />
      </geometry>
      <material
        name="">
        <color
          rgba="0.5 0.5 0.5 1" />
      </material>
    </visual>
  </link>
  <joint
    name="world_to_base"
    type="fixed">
    <parent
      link="world" />
    <child
      link="base_link" />
    <origin
      xyz="0 0 1"
      rpy="0 0 0" />
  </joint>
  <link
    name="riel">
    <inertial>
      <origin
        xyz="-0.0052 -0.01 0.44"
        rpy="0 0 0" />
      <mass
        value="0.71198" />
      <inertia
        ixx="0.045975"
        ixy="-2.2601E-21"
        ixz="-3.3958E-19"
        iyy="0.04606"
        iyz="1.3834E-20"
        izz="0.00014162" />
    </inertial>
    <visual>
      <origin
        xyz="0 0 0"
        rpy="0 0 0" />
      <geometry>
        <mesh
          filename="package://scara/meshes/riel.STL" />
      </geometry>
      <material
        name="">
        <color
          rgba="0.86667 0.9098 1 1" />
      </material>
    </visual>
    <collision>
      <origin
        xyz="0 0 0"
        rpy="0 0 0" />
      <geometry>
        <mesh
          filename="package://scara/meshes/riel.STL" />
      </geometry>
    </collision>
  </link>
  <joint
    name="base_to_riel"
    type="fixed">
    <origin
      xyz="0 0 0"
      rpy="1.5708 0 0" />
    <parent
      link="base_link" />
    <child
      link="riel" />
  </joint>
  <link
    name="carro">
    <inertial>
      <origin
        xyz="-0.033826 -0.027804 0.070708"
        rpy="0 0 0" />
      <mass
        value="0.4015" />
      <inertia
        ixx="3.7354E-05"
        ixy="-1.6408E-06"
        ixz="3.2962E-06"
        iyy="6.2799E-05"
        iyz="5.7265E-07"
        izz="4.541E-05" />
    </inertial>
    <visual>
      <origin
        xyz="0 0 0"
        rpy="0 0 0" />
      <geometry>
        <mesh
          filename="package://scara/meshes/carro.STL" />
      </geometry>
      <material
        name="">
        <color
          rgba="0.79216 0.81961 0.93333 1" />
      </material>
    </visual>
    <collision>
      <origin
        xyz="0 0 0"
        rpy="0 0 0" />
      <geometry>
        <mesh
          filename="package://scara/meshes/carro.STL" />
      </geometry>
    </collision>
  </link>
  <joint
    name="corredera"
    type="prismatic">
    <origin
      xyz="-0.0052 0.0015 0.40304"
      rpy="0 0 3.1416" />
    <parent
      link="riel" />
    <child
      link="carro" />
    <axis
      xyz="0 0 1" />
    <limit
      lower="-0.43"
      upper="0.43"
      effort="20"
      velocity="20" />
  </joint>
  <link
    name="pendulum_link">
    <inertial>
      <origin
        xyz="-1.2768E-15 -0.19577 0.020665"
        rpy="0 0 0" />
      <mass
        value="0.212" />
      <inertia
        ixx="0.0017534"
        ixy="-8.8623E-18"
        ixz="-1.2944E-19"
        iyy="0.00047667"
        iyz="6.4024E-19"
        izz="0.0012774" />
    </inertial>
    <visual>
      <origin
        xyz="0 0 0"
        rpy="0 0 0" />
      <geometry>
        <mesh
          filename="package://scara/meshes/pendulo.STL" />
      </geometry>
      <material
        name="">
        <color
          rgba="0.79216 0.81961 0.93333 1" />
      </material>
    </visual>
    <collision>
      <origin
        xyz="0 0 0"
        rpy="0 0 0" />
      <geometry>
        <mesh
          filename="package://scara/meshes/pendulo.STL" />
      </geometry>
    </collision>
  </link>
  <joint
    name="pendulum_joint"
    type="revolute">
    <origin
      xyz="-0.020665 -0.015276 0.044"
      rpy="0 -1.5708 3.1416" />
    <parent
      link="carro" />
    <child
      link="pendulum_link" />
    <axis
      xyz="0 0 -1" />
    <limit
      lower="-3.1416"
      upper="3.1416"
      effort="20"
      velocity="20" />
  </joint>
</robot>